[2022-03-14 19:29:47,256] {taskinstance.py:1032} INFO - Dependencies all met for <TaskInstance: xcom_dag.choose_model manual__2022-03-14T19:29:19.557221+00:00 [queued]>
[2022-03-14 19:29:47,271] {taskinstance.py:1032} INFO - Dependencies all met for <TaskInstance: xcom_dag.choose_model manual__2022-03-14T19:29:19.557221+00:00 [queued]>
[2022-03-14 19:29:47,271] {taskinstance.py:1238} INFO - 
--------------------------------------------------------------------------------
[2022-03-14 19:29:47,272] {taskinstance.py:1239} INFO - Starting attempt 1 of 1
[2022-03-14 19:29:47,272] {taskinstance.py:1240} INFO - 
--------------------------------------------------------------------------------
[2022-03-14 19:29:47,360] {taskinstance.py:1259} INFO - Executing <Task(BranchPythonOperator): choose_model> on 2022-03-14 19:29:19.557221+00:00
[2022-03-14 19:29:47,364] {standard_task_runner.py:52} INFO - Started process 8032 to run task
[2022-03-14 19:29:47,407] {standard_task_runner.py:76} INFO - Running: ['airflow', 'tasks', 'run', 'xcom_dag', 'choose_model', 'manual__2022-03-14T19:29:19.557221+00:00', '--job-id', '127', '--raw', '--subdir', 'DAGS_FOLDER/xcom_dag.py', '--cfg-path', '/tmp/tmpi0fdlo8p', '--error-file', '/tmp/tmpkc8kdgwm']
[2022-03-14 19:29:47,417] {standard_task_runner.py:77} INFO - Job 127: Subtask choose_model
[2022-03-14 19:29:48,154] {logging_mixin.py:109} INFO - Running <TaskInstance: xcom_dag.choose_model manual__2022-03-14T19:29:19.557221+00:00 [running]> on host airflowvm
[2022-03-14 19:29:49,964] {taskinstance.py:1424} INFO - Exporting the following env vars:
AIRFLOW_CTX_DAG_OWNER=airflow
AIRFLOW_CTX_DAG_ID=xcom_dag
AIRFLOW_CTX_TASK_ID=choose_model
AIRFLOW_CTX_EXECUTION_DATE=2022-03-14T19:29:19.557221+00:00
AIRFLOW_CTX_DAG_RUN_ID=manual__2022-03-14T19:29:19.557221+00:00
[2022-03-14 19:29:49,965] {logging_mixin.py:109} INFO - choose best model
[2022-03-14 19:29:50,111] {taskinstance.py:1700} ERROR - Task failed with exception
Traceback (most recent call last):
  File "/home/airflow/sandbox/lib/python3.8/site-packages/airflow/models/taskinstance.py", line 1329, in _run_raw_task
    self._execute_task_with_callbacks(context)
  File "/home/airflow/sandbox/lib/python3.8/site-packages/airflow/models/taskinstance.py", line 1455, in _execute_task_with_callbacks
    result = self._execute_task(context, self.task)
  File "/home/airflow/sandbox/lib/python3.8/site-packages/airflow/models/taskinstance.py", line 1511, in _execute_task
    result = execute_callable(context=context)
  File "/home/airflow/sandbox/lib/python3.8/site-packages/airflow/operators/python.py", line 203, in execute
    branch = super().execute(context)
  File "/home/airflow/sandbox/lib/python3.8/site-packages/airflow/operators/python.py", line 174, in execute
    return_value = self.execute_callable()
  File "/home/airflow/sandbox/lib/python3.8/site-packages/airflow/operators/python.py", line 185, in execute_callable
    return self.python_callable(*self.op_args, **self.op_kwargs)
  File "/home/airflow/airflow/dags/xcom_dag.py", line 28, in _choose_best_model
    if accuracy > 5:
TypeError: '>' not supported between instances of 'NoneType' and 'int'
[2022-03-14 19:29:50,421] {taskinstance.py:1267} INFO - Marking task as FAILED. dag_id=xcom_dag, task_id=choose_model, execution_date=20220314T192919, start_date=20220314T192947, end_date=20220314T192950
[2022-03-14 19:29:50,719] {standard_task_runner.py:89} ERROR - Failed to execute job 127 for task choose_model
Traceback (most recent call last):
  File "/home/airflow/sandbox/lib/python3.8/site-packages/airflow/task/task_runner/standard_task_runner.py", line 85, in _start_by_fork
    args.func(args, dag=self.dag)
  File "/home/airflow/sandbox/lib/python3.8/site-packages/airflow/cli/cli_parser.py", line 48, in command
    return func(*args, **kwargs)
  File "/home/airflow/sandbox/lib/python3.8/site-packages/airflow/utils/cli.py", line 92, in wrapper
    return f(*args, **kwargs)
  File "/home/airflow/sandbox/lib/python3.8/site-packages/airflow/cli/commands/task_command.py", line 298, in task_run
    _run_task_by_selected_method(args, dag, ti)
  File "/home/airflow/sandbox/lib/python3.8/site-packages/airflow/cli/commands/task_command.py", line 107, in _run_task_by_selected_method
    _run_raw_task(args, ti)
  File "/home/airflow/sandbox/lib/python3.8/site-packages/airflow/cli/commands/task_command.py", line 180, in _run_raw_task
    ti._run_raw_task(
  File "/home/airflow/sandbox/lib/python3.8/site-packages/airflow/utils/session.py", line 70, in wrapper
    return func(*args, session=session, **kwargs)
  File "/home/airflow/sandbox/lib/python3.8/site-packages/airflow/models/taskinstance.py", line 1329, in _run_raw_task
    self._execute_task_with_callbacks(context)
  File "/home/airflow/sandbox/lib/python3.8/site-packages/airflow/models/taskinstance.py", line 1455, in _execute_task_with_callbacks
    result = self._execute_task(context, self.task)
  File "/home/airflow/sandbox/lib/python3.8/site-packages/airflow/models/taskinstance.py", line 1511, in _execute_task
    result = execute_callable(context=context)
  File "/home/airflow/sandbox/lib/python3.8/site-packages/airflow/operators/python.py", line 203, in execute
    branch = super().execute(context)
  File "/home/airflow/sandbox/lib/python3.8/site-packages/airflow/operators/python.py", line 174, in execute
    return_value = self.execute_callable()
  File "/home/airflow/sandbox/lib/python3.8/site-packages/airflow/operators/python.py", line 185, in execute_callable
    return self.python_callable(*self.op_args, **self.op_kwargs)
  File "/home/airflow/airflow/dags/xcom_dag.py", line 28, in _choose_best_model
    if accuracy > 5:
TypeError: '>' not supported between instances of 'NoneType' and 'int'
[2022-03-14 19:29:50,801] {local_task_job.py:154} INFO - Task exited with return code 1
[2022-03-14 19:29:51,756] {local_task_job.py:264} INFO - 0 downstream tasks scheduled from follow-on schedule check
