[2022-01-11 20:18:06,286] {taskinstance.py:1032} INFO - Dependencies all met for <TaskInstance: parallel_dag.task_02 scheduled__2022-01-06T00:00:00+00:00 [queued]>
[2022-01-11 20:18:06,519] {taskinstance.py:1032} INFO - Dependencies all met for <TaskInstance: parallel_dag.task_02 scheduled__2022-01-06T00:00:00+00:00 [queued]>
[2022-01-11 20:18:06,520] {taskinstance.py:1238} INFO - 
--------------------------------------------------------------------------------
[2022-01-11 20:18:06,520] {taskinstance.py:1239} INFO - Starting attempt 1 of 1
[2022-01-11 20:18:06,520] {taskinstance.py:1240} INFO - 
--------------------------------------------------------------------------------
[2022-01-11 20:18:06,638] {taskinstance.py:1259} INFO - Executing <Task(BashOperator): task_02> on 2022-01-06 00:00:00+00:00
[2022-01-11 20:18:06,653] {standard_task_runner.py:52} INFO - Started process 5401 to run task
[2022-01-11 20:18:06,676] {standard_task_runner.py:76} INFO - Running: ['airflow', 'tasks', 'run', 'parallel_dag', 'task_02', 'scheduled__2022-01-06T00:00:00+00:00', '--job-id', '45', '--raw', '--subdir', 'DAGS_FOLDER/parallel_dags.py', '--cfg-path', '/tmp/tmpwdbz27a7', '--error-file', '/tmp/tmpr1typ8fd']
[2022-01-11 20:18:06,685] {standard_task_runner.py:77} INFO - Job 45: Subtask task_02
[2022-01-11 20:18:11,551] {logging_mixin.py:109} INFO - Running <TaskInstance: parallel_dag.task_02 scheduled__2022-01-06T00:00:00+00:00 [running]> on host airflowvm
[2022-01-11 20:18:13,176] {standard_task_runner.py:89} ERROR - Failed to execute job 45 for task task_02
Traceback (most recent call last):
  File "/home/airflow/sandbox/lib/python3.8/site-packages/airflow/task/task_runner/standard_task_runner.py", line 85, in _start_by_fork
    args.func(args, dag=self.dag)
  File "/home/airflow/sandbox/lib/python3.8/site-packages/airflow/cli/cli_parser.py", line 48, in command
    return func(*args, **kwargs)
  File "/home/airflow/sandbox/lib/python3.8/site-packages/airflow/utils/cli.py", line 92, in wrapper
    return f(*args, **kwargs)
  File "/home/airflow/sandbox/lib/python3.8/site-packages/airflow/cli/commands/task_command.py", line 298, in task_run
    _run_task_by_selected_method(args, dag, ti)
  File "/home/airflow/sandbox/lib/python3.8/site-packages/airflow/cli/commands/task_command.py", line 107, in _run_task_by_selected_method
    _run_raw_task(args, ti)
  File "/home/airflow/sandbox/lib/python3.8/site-packages/airflow/cli/commands/task_command.py", line 180, in _run_raw_task
    ti._run_raw_task(
  File "/home/airflow/sandbox/lib/python3.8/site-packages/airflow/utils/session.py", line 70, in wrapper
    return func(*args, session=session, **kwargs)
  File "/home/airflow/sandbox/lib/python3.8/site-packages/airflow/models/taskinstance.py", line 1322, in _run_raw_task
    session.commit()
  File "/home/airflow/sandbox/lib/python3.8/site-packages/sqlalchemy/orm/session.py", line 1046, in commit
    self.transaction.commit()
  File "/home/airflow/sandbox/lib/python3.8/site-packages/sqlalchemy/orm/session.py", line 504, in commit
    self._prepare_impl()
  File "/home/airflow/sandbox/lib/python3.8/site-packages/sqlalchemy/orm/session.py", line 483, in _prepare_impl
    self.session.flush()
  File "/home/airflow/sandbox/lib/python3.8/site-packages/sqlalchemy/orm/session.py", line 2540, in flush
    self._flush(objects)
  File "/home/airflow/sandbox/lib/python3.8/site-packages/sqlalchemy/orm/session.py", line 2682, in _flush
    transaction.rollback(_capture_exception=True)
  File "/home/airflow/sandbox/lib/python3.8/site-packages/sqlalchemy/util/langhelpers.py", line 68, in __exit__
    compat.raise_(
  File "/home/airflow/sandbox/lib/python3.8/site-packages/sqlalchemy/util/compat.py", line 182, in raise_
    raise exception
  File "/home/airflow/sandbox/lib/python3.8/site-packages/sqlalchemy/orm/session.py", line 2642, in _flush
    flush_context.execute()
  File "/home/airflow/sandbox/lib/python3.8/site-packages/sqlalchemy/orm/unitofwork.py", line 422, in execute
    rec.execute(self)
  File "/home/airflow/sandbox/lib/python3.8/site-packages/sqlalchemy/orm/unitofwork.py", line 586, in execute
    persistence.save_obj(
  File "/home/airflow/sandbox/lib/python3.8/site-packages/sqlalchemy/orm/persistence.py", line 230, in save_obj
    _emit_update_statements(
  File "/home/airflow/sandbox/lib/python3.8/site-packages/sqlalchemy/orm/persistence.py", line 1025, in _emit_update_statements
    raise orm_exc.StaleDataError(
sqlalchemy.orm.exc.StaleDataError: UPDATE statement on table 'task_instance' expected to update 1 row(s); 0 were matched.
[2022-01-11 20:18:13,280] {local_task_job.py:154} INFO - Task exited with return code 1
