[2022-03-15 19:32:12,135] {taskinstance.py:1032} INFO - Dependencies all met for <TaskInstance: trigger_rule.task_1 manual__2022-03-15T19:32:04.801871+00:00 [queued]>
[2022-03-15 19:32:12,379] {taskinstance.py:1032} INFO - Dependencies all met for <TaskInstance: trigger_rule.task_1 manual__2022-03-15T19:32:04.801871+00:00 [queued]>
[2022-03-15 19:32:12,379] {taskinstance.py:1238} INFO - 
--------------------------------------------------------------------------------
[2022-03-15 19:32:12,382] {taskinstance.py:1239} INFO - Starting attempt 1 of 1
[2022-03-15 19:32:12,386] {taskinstance.py:1240} INFO - 
--------------------------------------------------------------------------------
[2022-03-15 19:32:12,539] {taskinstance.py:1259} INFO - Executing <Task(BashOperator): task_1> on 2022-03-15 19:32:04.801871+00:00
[2022-03-15 19:32:12,549] {standard_task_runner.py:52} INFO - Started process 11169 to run task
[2022-03-15 19:32:12,629] {standard_task_runner.py:76} INFO - Running: ['airflow', 'tasks', 'run', 'trigger_rule', 'task_1', 'manual__2022-03-15T19:32:04.801871+00:00', '--job-id', '152', '--raw', '--subdir', 'DAGS_FOLDER/trigger_rule.py', '--cfg-path', '/tmp/tmpi66eqwz9', '--error-file', '/tmp/tmpwsyn0wld']
[2022-03-15 19:32:12,685] {standard_task_runner.py:77} INFO - Job 152: Subtask task_1
[2022-03-15 19:32:14,123] {logging_mixin.py:109} INFO - Running <TaskInstance: trigger_rule.task_1 manual__2022-03-15T19:32:04.801871+00:00 [running]> on host airflowvm
[2022-03-15 19:32:15,246] {taskinstance.py:1424} INFO - Exporting the following env vars:
AIRFLOW_CTX_DAG_OWNER=airflow
AIRFLOW_CTX_DAG_ID=trigger_rule
AIRFLOW_CTX_TASK_ID=task_1
AIRFLOW_CTX_EXECUTION_DATE=2022-03-15T19:32:04.801871+00:00
AIRFLOW_CTX_DAG_RUN_ID=manual__2022-03-15T19:32:04.801871+00:00
[2022-03-15 19:32:15,248] {subprocess.py:62} INFO - Tmp dir root location: 
 /tmp
[2022-03-15 19:32:15,249] {subprocess.py:74} INFO - Running command: ['bash', '-c', 'exit 1']
[2022-03-15 19:32:15,347] {subprocess.py:85} INFO - Output:
[2022-03-15 19:32:15,351] {subprocess.py:93} INFO - Command exited with return code 1
[2022-03-15 19:32:15,800] {taskinstance.py:1700} ERROR - Task failed with exception
Traceback (most recent call last):
  File "/home/airflow/sandbox/lib/python3.8/site-packages/airflow/models/taskinstance.py", line 1329, in _run_raw_task
    self._execute_task_with_callbacks(context)
  File "/home/airflow/sandbox/lib/python3.8/site-packages/airflow/models/taskinstance.py", line 1455, in _execute_task_with_callbacks
    result = self._execute_task(context, self.task)
  File "/home/airflow/sandbox/lib/python3.8/site-packages/airflow/models/taskinstance.py", line 1511, in _execute_task
    result = execute_callable(context=context)
  File "/home/airflow/sandbox/lib/python3.8/site-packages/airflow/operators/bash.py", line 187, in execute
    raise AirflowException(
airflow.exceptions.AirflowException: Bash command failed. The command returned a non-zero exit code 1.
[2022-03-15 19:32:15,939] {taskinstance.py:1267} INFO - Marking task as FAILED. dag_id=trigger_rule, task_id=task_1, execution_date=20220315T193204, start_date=20220315T193212, end_date=20220315T193215
[2022-03-15 19:32:16,127] {standard_task_runner.py:89} ERROR - Failed to execute job 152 for task task_1
Traceback (most recent call last):
  File "/home/airflow/sandbox/lib/python3.8/site-packages/airflow/task/task_runner/standard_task_runner.py", line 85, in _start_by_fork
    args.func(args, dag=self.dag)
  File "/home/airflow/sandbox/lib/python3.8/site-packages/airflow/cli/cli_parser.py", line 48, in command
    return func(*args, **kwargs)
  File "/home/airflow/sandbox/lib/python3.8/site-packages/airflow/utils/cli.py", line 92, in wrapper
    return f(*args, **kwargs)
  File "/home/airflow/sandbox/lib/python3.8/site-packages/airflow/cli/commands/task_command.py", line 298, in task_run
    _run_task_by_selected_method(args, dag, ti)
  File "/home/airflow/sandbox/lib/python3.8/site-packages/airflow/cli/commands/task_command.py", line 107, in _run_task_by_selected_method
    _run_raw_task(args, ti)
  File "/home/airflow/sandbox/lib/python3.8/site-packages/airflow/cli/commands/task_command.py", line 180, in _run_raw_task
    ti._run_raw_task(
  File "/home/airflow/sandbox/lib/python3.8/site-packages/airflow/utils/session.py", line 70, in wrapper
    return func(*args, session=session, **kwargs)
  File "/home/airflow/sandbox/lib/python3.8/site-packages/airflow/models/taskinstance.py", line 1329, in _run_raw_task
    self._execute_task_with_callbacks(context)
  File "/home/airflow/sandbox/lib/python3.8/site-packages/airflow/models/taskinstance.py", line 1455, in _execute_task_with_callbacks
    result = self._execute_task(context, self.task)
  File "/home/airflow/sandbox/lib/python3.8/site-packages/airflow/models/taskinstance.py", line 1511, in _execute_task
    result = execute_callable(context=context)
  File "/home/airflow/sandbox/lib/python3.8/site-packages/airflow/operators/bash.py", line 187, in execute
    raise AirflowException(
airflow.exceptions.AirflowException: Bash command failed. The command returned a non-zero exit code 1.
[2022-03-15 19:32:16,219] {local_task_job.py:154} INFO - Task exited with return code 1
[2022-03-15 19:32:16,870] {local_task_job.py:264} INFO - 0 downstream tasks scheduled from follow-on schedule check
